I'm sorry, but an uncaught exception occurred.

While running game code:
  File "game/script.rpy", line 228, in script
    show dp library (1) with dissolve
Exception: Image 'dp library' does not accept attributes '(1)'.

-- Full Traceback ------------------------------------------------------------

Full traceback:
  File "game/script.rpy", line 228, in script
    show dp library (1) with dissolve
  File "C:\Users\liuch\Downloads\renpy-8.0.3-sdk/renpy/ast.py", line 1408, in execute
    show_imspec(self.imspec, atl=getattr(self, "atl", None))
  File "C:\Users\liuch\Downloads\renpy-8.0.3-sdk/renpy/ast.py", line 1378, in show_imspec
    atl=atl)
  File "C:\Users\liuch\Downloads\renpy-8.0.3-sdk/renpy/exports.py", line 686, in show
    if not base.find_target() and renpy.config.missing_show:
  File "C:\Users\liuch\Downloads\renpy-8.0.3-sdk/renpy/display/image.py", line 414, in find_target
    self.target = target._duplicate(a)
  File "C:\Users\liuch\Downloads\renpy-8.0.3-sdk/renpy/display/core.py", line 397, in _duplicate
    args.extraneous()
  File "C:\Users\liuch\Downloads\renpy-8.0.3-sdk/renpy/display/core.py", line 267, in extraneous
    " ".join(self.args),
Exception: Image 'dp library' does not accept attributes '(1)'.

Windows-10-10.0.22000 AMD64
Ren'Py 7.5.3.22090809
 
Mon Nov 14 23:34:35 2022
